<?xml version="1.0" ?>
 
<robot name="baebot_sim" xmlns:xacro="https://www.ros.org/wiki/xacro" >
  <!--Import Plugins-->
  <xacro:include filename="$(find baebot_sim)/urdf/baebot_sim.gazebo" />
  
  <!--Link (robot_footprint)-->
  <link name="robot_footprint"></link>

  <!--Joint (robot_footprint)-->
  <joint name="robot_footprint_joint" type="fixed">
    <origin xyz="0 0 0" rpy="0 0 0" />
    <parent link="robot_footprint"/>
    <child link="chassis" />
  </joint>
  
  <!--Link (chasiss)-->
  <link name="chassis">
    <pose>0 0 0.1 0 0 0</pose>
    
    <inertial>
      <mass value="1"/>
      <origin xyz="0 0 0" rpy="0 0 0"/>
      <inertia 
          ixx="0.035" ixy="0" ixz="0"
          iyy="0.035" iyz="0"
          izz="0.035"  
      />
    </inertial>
    
    <collision name="chassis_collision">
      <geometry>
        <box size="0.125 0.125 0.085"/>
      </geometry>
    </collision>
    
    <visual name='chassis_visual'>
      <origin rpy="0 0 0" xyz="0 0 0"/>
      <geometry>
        <box size="0.125 0.125 0.085"/>
      </geometry>
    </visual>
    
    <!--rear caster-->
    <collision name="front_caster_collision">
      <origin xyz="-0.04 0 -0.035" rpy=" 0 0 0"/>
      <geometry>
        <sphere radius="0.015"/>
      </geometry>
    </collision>

    <visual name="front_caster_visual">
      <origin xyz="-0.04 0 -0.035" rpy=" 0 0 0"/>
      <geometry>
        <sphere radius="0.015"/>
      </geometry>
    </visual>
  </link>
  
  <!--Link (left_wheel)-->  
  <link name='left_wheel'>    
    <inertial>
      <mass value="0.1"/>
      <origin xyz="0 0 0" rpy="0 1.5707 1.5707" />
      <inertia
          ixx="0.015" ixy="0" ixz="0"
          iyy="0.015" iyz="0"
          izz="0.013"
      />
    </inertial>
    
    <collision name='left_wheel_collision'>
      <origin xyz="0 0 0" rpy="0 1.5707 1.5707"/>
      <geometry>
        <cylinder length="0.025" radius="0.03"/>
      </geometry>
    </collision>
    
    <visual name='left_wheel_visual'>
      <origin xyz="0 0 0" rpy="0 1.5707 1.5707"/>
      <geometry>
        <cylinder length="0.025" radius="0.03"/>
      </geometry>  
    </visual>
    
  </link>
    
  <!--Joint (left_wheel_hinge)-->
  <joint name="left_wheel_hinge" type="continuous">
    <origin xyz="0.035 0.078 -0.02" rpy="0 0 0"/>
    <child link="left_wheel" />
    <parent link="chassis"/>
    <axis xyz="0 1 0" rpy="0 0 0" />
    <limit effort="1" velocity="1.5"/>
    <joint_properties damping="1.0" friction="1.0" />
  </joint>  
    
  <!--Link (right_wheel)-->
  <link name="right_wheel">    
    <inertial>
      <origin xyz="0 0 0" rpy="0 1.5707 1.5707" />
      <mass value="0.1"/>
      <inertia
          ixx="0.015" ixy="0" ixz="0"
          iyy="0.015" iyz="0"
          izz="0.013"
      />
    </inertial>
    
    <collision name="right_wheel_collision">
      <origin xyz="0 0 0" rpy="0 1.5707 1.5707"/>
      <geometry>
        <cylinder length="0.025" radius="0.03"/>
      </geometry>
    </collision>
    
    <visual name="right_wheel_visual">
      <origin xyz="0 0 0" rpy="0 1.5707 1.5707"/>
      <geometry>
        <cylinder length="0.025" radius="0.03"/>
      </geometry>      
    </visual>  
  </link>
    
  <!--Joint (right_wheel_hinge)-->
  <joint name="right_wheel_hinge" type="continuous">
    <origin xyz="0.035 -0.078 -0.02" rpy="0 0 0"/>
    <child link="right_wheel" />
    <parent link="chassis"/>
    <axis rpy="0 0 0" xyz="0 1 0"/>
    <limit effort="1" velocity="1.5"/>
    <joint_properties damping="1.0" friction="1.0" />
  </joint>

  <!--Link (camera)-->
  <link name='camera'>
    <inertial>
      <origin xyz="0 0 0" rpy="0 0 0"/>
      <mass value="0.05"/>
      <box_inertia m="0.1" x="0.05" y="0.05" z="0.05"/>
      <inertia
          ixx="1e-6" ixy="0" ixz="0"
          iyy="1e-6" iyz="0"
          izz="1e-6"
      />
    </inertial>

    <visual name='camera_visual'>
      <origin xyz="0 0 0" rpy="0 0 0"/>
      <geometry>
        <box size=".001 .025 .025"/>
      </geometry>
    </visual>

    <collision name='camera_collision'>
      <origin xyz="0 0 0" rpy="0 0 0"/>
      <geometry>
        <box size=".001 .025 .025"/>
      </geometry>
    </collision>
  </link>

  <!--Joint (camera)-->
  <joint type="fixed" name="camera_joint">
    <origin xyz="0.063 0 0" rpy="0 0 0"/>
    <child link="camera"/>
    <parent link="chassis"/>
    <axis xyz="0 1 0"/>
  </joint>

  <!--Links (hokuyo)-->
  <link name='hokuyo'>
    <inertial>
      <origin xyz="0 0 0" rpy="0 0 0"/>
      <mass value="1e-5"/>
      <inertia
          ixx="1e-6" ixy="0" ixz="0"
          iyy="1e-6" iyz="0"
          izz="1e-6"
      />
    </inertial>

    <visual name='hokuyo_visual'>
      <origin xyz="0 0 0" rpy="0 0 0"/>
      <geometry>
        <mesh filename="package://baebot_sim/meshes/hokuyo.dae"/>
      </geometry>
    </visual>

    <collision name='hokuyo_collision'>
      <origin xyz="0 0 0" rpy="0 0 0"/>
      <geometry>
        <box size=".1 .1 .1"/>
      </geometry>
    </collision>
  </link>

  <!--Joint (hokuyo)-->
  <joint type="fixed" name="hokuyo_joint">
    <origin xyz="0.037 0 .078" rpy="0 0 0"/>
    <child link="hokuyo"/>
    <parent link="chassis"/>
    <axis xyz="0 1 0"/>
  </joint>

  <!--give your robot some color-->
  <gazebo reference="chassis">
    <material>Gazebo/Black</material>
  </gazebo>

  <gazebo reference="left_wheel">
    <material>Gazebo/White</material>
  </gazebo>

  <gazebo reference="right_wheel">
    <material>Gazebo/White</material>
  </gazebo>

  <gazebo reference="camera">
    <material>Gazebo/White</material>
  </gazebo>

  <gazebo reference="hokuyo">
    <material>Gazebo/Yellow</material>
  </gazebo>    
  
</robot>
